starting the process at: 2025-04-27 08:30:01
/home/dungnt378/Desktop/work/SLA_PROBE/SLA_GAME/sla_del.sh: 5: source: not found
Running main.py as script
Mode selected: del
FILE BROWSER MODE: del
connected
Deleted:/SLA_GAME
DONE
starting the process at: 2025-05-04 08:30:01
/home/dungnt378/Desktop/work/SLA_PROBE/SLA_GAME/sla_del.sh: 5: source: not found
Running main.py as script
Mode selected: del
FILE BROWSER MODE: del
Traceback (most recent call last):
  File "/home/dungnt378/Desktop/work/SLA_PROBE/venv/lib/python3.12/site-packages/aiohttp/connector.py", line 1115, in _wrap_create_connection
    sock = await aiohappyeyeballs.start_connection(
           ^^^^^^^^^^^^^^^^^^^^^^^^^^^^^^^^^^^^^^^^
  File "/home/dungnt378/Desktop/work/SLA_PROBE/venv/lib/python3.12/site-packages/aiohappyeyeballs/impl.py", line 122, in start_connection
    raise first_exception
  File "/home/dungnt378/Desktop/work/SLA_PROBE/venv/lib/python3.12/site-packages/aiohappyeyeballs/impl.py", line 73, in start_connection
    sock = await _connect_sock(
           ^^^^^^^^^^^^^^^^^^^^
  File "/home/dungnt378/Desktop/work/SLA_PROBE/venv/lib/python3.12/site-packages/aiohappyeyeballs/impl.py", line 208, in _connect_sock
    await loop.sock_connect(sock, address)
  File "/usr/lib/python3.12/asyncio/selector_events.py", line 651, in sock_connect
    return await fut
           ^^^^^^^^^
  File "/usr/lib/python3.12/asyncio/selector_events.py", line 691, in _sock_connect_cb
    raise OSError(err, f'Connect call failed {address}')
ConnectionRefusedError: [Errno 111] Connect call failed ('127.0.0.1', 8080)

The above exception was the direct cause of the following exception:

Traceback (most recent call last):
  File "/home/dungnt378/Desktop/work/SLA_PROBE/SLA_GAME/fetch_SLA_data.py", line 167, in <module>
    main(args.m)
  File "/home/dungnt378/Desktop/work/SLA_PROBE/SLA_GAME/fetch_SLA_data.py", line 157, in main
    filebrowseraction(file=file, args=mode)
  File "/home/dungnt378/Desktop/work/SLA_PROBE/SLA_GAME/action.py", line 20, in filebrowseraction
    asyncio.run(connect(file,args))
  File "/usr/lib/python3.12/asyncio/runners.py", line 194, in run
    return runner.run(main)
           ^^^^^^^^^^^^^^^^
  File "/usr/lib/python3.12/asyncio/runners.py", line 118, in run
    return self._loop.run_until_complete(task)
           ^^^^^^^^^^^^^^^^^^^^^^^^^^^^^^^^^^^
  File "/usr/lib/python3.12/asyncio/base_events.py", line 687, in run_until_complete
    return future.result()
           ^^^^^^^^^^^^^^^
  File "/home/dungnt378/Desktop/work/SLA_PROBE/SLA_GAME/action.py", line 7, in connect
    await client.connect()
  File "/home/dungnt378/Desktop/work/SLA_PROBE/venv/lib/python3.12/site-packages/filebrowser_client/client.py", line 54, in connect
    async with session.post(
  File "/home/dungnt378/Desktop/work/SLA_PROBE/venv/lib/python3.12/site-packages/aiohttp/client.py", line 1425, in __aenter__
    self._resp: _RetType = await self._coro
                           ^^^^^^^^^^^^^^^^
  File "/home/dungnt378/Desktop/work/SLA_PROBE/venv/lib/python3.12/site-packages/aiohttp/client.py", line 703, in _request
    conn = await self._connector.connect(
           ^^^^^^^^^^^^^^^^^^^^^^^^^^^^^^
  File "/home/dungnt378/Desktop/work/SLA_PROBE/venv/lib/python3.12/site-packages/aiohttp/connector.py", line 548, in connect
    proto = await self._create_connection(req, traces, timeout)
            ^^^^^^^^^^^^^^^^^^^^^^^^^^^^^^^^^^^^^^^^^^^^^^^^^^^
  File "/home/dungnt378/Desktop/work/SLA_PROBE/venv/lib/python3.12/site-packages/aiohttp/connector.py", line 1056, in _create_connection
    _, proto = await self._create_direct_connection(req, traces, timeout)
               ^^^^^^^^^^^^^^^^^^^^^^^^^^^^^^^^^^^^^^^^^^^^^^^^^^^^^^^^^^
  File "/home/dungnt378/Desktop/work/SLA_PROBE/venv/lib/python3.12/site-packages/aiohttp/connector.py", line 1406, in _create_direct_connection
    raise last_exc
  File "/home/dungnt378/Desktop/work/SLA_PROBE/venv/lib/python3.12/site-packages/aiohttp/connector.py", line 1375, in _create_direct_connection
    transp, proto = await self._wrap_create_connection(
                    ^^^^^^^^^^^^^^^^^^^^^^^^^^^^^^^^^^^
  File "/home/dungnt378/Desktop/work/SLA_PROBE/venv/lib/python3.12/site-packages/aiohttp/connector.py", line 1130, in _wrap_create_connection
    raise client_error(req.connection_key, exc) from exc
aiohttp.client_exceptions.ClientConnectorError: Cannot connect to host localhost:8080 ssl:default [Connect call failed ('127.0.0.1', 8080)]
starting the process at: 2025-05-11 08:30:01
/home/dungnt378/Desktop/work/SLA_PROBE/SLA_GAME/sla_del.sh: 5: source: not found
Running main.py as script
Mode selected: del
FILE BROWSER MODE: del
Traceback (most recent call last):
  File "/home/dungnt378/Desktop/work/SLA_PROBE/venv/lib/python3.12/site-packages/aiohttp/connector.py", line 1115, in _wrap_create_connection
    sock = await aiohappyeyeballs.start_connection(
           ^^^^^^^^^^^^^^^^^^^^^^^^^^^^^^^^^^^^^^^^
  File "/home/dungnt378/Desktop/work/SLA_PROBE/venv/lib/python3.12/site-packages/aiohappyeyeballs/impl.py", line 122, in start_connection
    raise first_exception
  File "/home/dungnt378/Desktop/work/SLA_PROBE/venv/lib/python3.12/site-packages/aiohappyeyeballs/impl.py", line 73, in start_connection
    sock = await _connect_sock(
           ^^^^^^^^^^^^^^^^^^^^
  File "/home/dungnt378/Desktop/work/SLA_PROBE/venv/lib/python3.12/site-packages/aiohappyeyeballs/impl.py", line 208, in _connect_sock
    await loop.sock_connect(sock, address)
  File "/usr/lib/python3.12/asyncio/selector_events.py", line 651, in sock_connect
    return await fut
           ^^^^^^^^^
  File "/usr/lib/python3.12/asyncio/selector_events.py", line 691, in _sock_connect_cb
    raise OSError(err, f'Connect call failed {address}')
ConnectionRefusedError: [Errno 111] Connect call failed ('127.0.0.1', 8080)

The above exception was the direct cause of the following exception:

Traceback (most recent call last):
  File "/home/dungnt378/Desktop/work/SLA_PROBE/SLA_GAME/fetch_SLA_data.py", line 172, in <module>
    main(args.m)
  File "/home/dungnt378/Desktop/work/SLA_PROBE/SLA_GAME/fetch_SLA_data.py", line 162, in main
    filebrowseraction(file=file, args=mode)
  File "/home/dungnt378/Desktop/work/SLA_PROBE/SLA_GAME/action.py", line 20, in filebrowseraction
    asyncio.run(connect(file,args))
  File "/usr/lib/python3.12/asyncio/runners.py", line 194, in run
    return runner.run(main)
           ^^^^^^^^^^^^^^^^
  File "/usr/lib/python3.12/asyncio/runners.py", line 118, in run
    return self._loop.run_until_complete(task)
           ^^^^^^^^^^^^^^^^^^^^^^^^^^^^^^^^^^^
  File "/usr/lib/python3.12/asyncio/base_events.py", line 687, in run_until_complete
    return future.result()
           ^^^^^^^^^^^^^^^
  File "/home/dungnt378/Desktop/work/SLA_PROBE/SLA_GAME/action.py", line 7, in connect
    await client.connect()
  File "/home/dungnt378/Desktop/work/SLA_PROBE/venv/lib/python3.12/site-packages/filebrowser_client/client.py", line 54, in connect
    async with session.post(
  File "/home/dungnt378/Desktop/work/SLA_PROBE/venv/lib/python3.12/site-packages/aiohttp/client.py", line 1425, in __aenter__
    self._resp: _RetType = await self._coro
                           ^^^^^^^^^^^^^^^^
  File "/home/dungnt378/Desktop/work/SLA_PROBE/venv/lib/python3.12/site-packages/aiohttp/client.py", line 703, in _request
    conn = await self._connector.connect(
           ^^^^^^^^^^^^^^^^^^^^^^^^^^^^^^
  File "/home/dungnt378/Desktop/work/SLA_PROBE/venv/lib/python3.12/site-packages/aiohttp/connector.py", line 548, in connect
    proto = await self._create_connection(req, traces, timeout)
            ^^^^^^^^^^^^^^^^^^^^^^^^^^^^^^^^^^^^^^^^^^^^^^^^^^^
  File "/home/dungnt378/Desktop/work/SLA_PROBE/venv/lib/python3.12/site-packages/aiohttp/connector.py", line 1056, in _create_connection
    _, proto = await self._create_direct_connection(req, traces, timeout)
               ^^^^^^^^^^^^^^^^^^^^^^^^^^^^^^^^^^^^^^^^^^^^^^^^^^^^^^^^^^
  File "/home/dungnt378/Desktop/work/SLA_PROBE/venv/lib/python3.12/site-packages/aiohttp/connector.py", line 1406, in _create_direct_connection
    raise last_exc
  File "/home/dungnt378/Desktop/work/SLA_PROBE/venv/lib/python3.12/site-packages/aiohttp/connector.py", line 1375, in _create_direct_connection
    transp, proto = await self._wrap_create_connection(
                    ^^^^^^^^^^^^^^^^^^^^^^^^^^^^^^^^^^^
  File "/home/dungnt378/Desktop/work/SLA_PROBE/venv/lib/python3.12/site-packages/aiohttp/connector.py", line 1130, in _wrap_create_connection
    raise client_error(req.connection_key, exc) from exc
aiohttp.client_exceptions.ClientConnectorError: Cannot connect to host localhost:8080 ssl:default [Connect call failed ('127.0.0.1', 8080)]
